Workbook
Name products: products!$1:$1000
Name product_id: events!$N$2:$N$1331
Name total_revenue: events!$U$2:$U$1331
Name countries: countries!$1:$1000
Name total_profit: events!$W$2:$W$1331
Name total_cost: events!$V$2:$V$1331

Sheet countries
A1: alpha-3 | B1: name | C1: alpha-2 | D1: alpha-3 | E1: region | F1: sub-region
A2: AFG | B2: Afghanistan | C2: AF | D2: AFG | E2: Asia | F2: Southern Asia
A3: ALA | B3: Åland Islands | C3: AX | D3: ALA | E3: Europe | F3: Northern Europe
A4: ALB | B4: Albania | C4: AL | D4: ALB | E4: Europe | F4: Southern Europe
A5: DZA | B5: Algeria | C5: DZ | D5: DZA | E5: Africa | F5: Northern Africa
A6: ASM | B6: American Samoa | C6: AS | D6: ASM | E6: Oceania | F6: Polynesia
A7: AND | B7: Andorra | C7: AD | D7: AND | E7: Europe | F7: Southern Europe
A8: AGO | B8: Angola | C8: AO | D8: AGO | E8: Africa | F8: Sub-Saharan Africa
A9: AIA | B9: Anguilla | C9: AI | D9: AIA | E9: Americas | F9: Latin America and the Caribbean
A10: ATA | B10: Antarctica | C10: AQ | D10: ATA | E10: Antarctic | F10: Antarctic
A11: ATG | B11: Antigua and Barbuda | C11: AG | D11: ATG | E11: Americas | F11: Latin America and the Caribbean
A12: ARG | B12: Argentina | C12: AR | D12: ARG | E12: Americas | F12: Latin America and the Caribbean
... A250: ZWE | B250: Zimbabwe | C250: ZW | D250: ZWE | E250: Africa | F250: Sub-Saharan Africa

Sheet events
A1: Order ID | B1: Order Date | C1: Year of order | D1: Month of order | E1: Weekday | F1: Number of weekday | G1: Ship Date | H1: Shipping Duration | I1: Order Priority | J1: Country Code | K1: Countries | L1: region | M1: sub-region | N1: Product ID | O1: Category | P1: Sales Channel | Q1: Units Sold | R1: Unit Price | S1: Unit Cost | U1: total revenue | V1: total cost | W1: total profit
A2: 100640618 | B2: 41920 | C2: =YEAR(B2) -> 2014 | D2: =TEXT(B2,"MM - MMM") -> 10 - Oct | E2: =CHOOSE(WEEKDAY(B2,2),"Mon","Tue","Wed","Thu","Fri","Sat","Sun") -> Wed | F2: =MATCH(E2,{"Mon","Tue","Wed","Thu","Fri","Sat","Sun"}, 0) -> 3 | G2: 41930 | H2: =(DATEDIF(B2,G2,"D")) -> 10 | I2: M | J2: NOR | K2: =VLOOKUP(J2,countries,2,false) -> Norway | L2: =VLOOKUP($J2,countries,5,false) -> Europe | M2: =VLOOKUP($J2,countries,6,false) -> Northern Europe | N2: 2103 | O2: =VLOOKUP(N2, products, 2, FALSE) -> Cereal | P2: Online | Q2: 650 | R2: 205.7 | S2: 117.11 | U2: =Q2*R2 -> 133705 | V2: =Q2*S2 -> 76121.5 | W2: =U2-V2 -> 57583.5
A3: 100983083 | B3: 42593 | C3: =YEAR(B3) -> 2016 | D3: =TEXT(B3,"MM - MMM") -> 08 - Aug | E3: =CHOOSE(WEEKDAY(B3,2),"Mon","Tue","Wed","Thu","Fri","Sat","Sun") -> Thu | F3: =MATCH(E3,{"Mon","Tue","Wed","Thu","Fri","Sat","Sun"}, 0) -> 4 | G3: 42593 | H3: =(DATEDIF(B3,G3,"D")) -> 0 | I3: C | J3: SRB | K3: =VLOOKUP(J3,countries,2,false) -> Serbia | L3: =VLOOKUP($J3,countries,5,false) -> Europe | M3: =VLOOKUP($J3,countries,6,false) -> Southern Europe | N3: 2103 | O3: =VLOOKUP(N3, products, 2, FALSE) -> Cereal | P3: Offline | Q3: 1993 | R3: 205.7 | S3: 117.11 | U3: =Q3*R3 -> 409960.1 | V3: =Q3*S3 -> 233400.23 | W3: =U3-V3 -> 176559.87
A4: 101025998 | B4: 41838 | C4: =YEAR(B4) -> 2014 | D4: =TEXT(B4,"MM - MMM") -> 07 - Jul | E4: =CHOOSE(WEEKDAY(B4,2),"Mon","Tue","Wed","Thu","Fri","Sat","Sun") -> Fri | F4: =MATCH(E4,{"Mon","Tue","Wed","Thu","Fri","Sat","Sun"}, 0) -> 5 | G4: 41862 | H4: =(DATEDIF(B4,G4,"D")) -> 24 | I4: M | J4: Unknown | K4: Unknown | L4: Unknown | M4: Unknown | N4: 7940 | O4: =VLOOKUP(N4, products, 2, FALSE) -> Household | P4: Online | Q4: 4693 | R4: 668.27 | S4: 502.54 | U4: =Q4*R4 -> 3136191.1 | V4: =Q4*S4 -> 2358420.2 | W4: =U4-V4 -> 777770.89
A5: 102230632 | B5: 42868 | C5: =YEAR(B5) -> 2017 | D5: =TEXT(B5,"MM - MMM") -> 05 - May | E5: =CHOOSE(WEEKDAY(B5,2),"Mon","Tue","Wed","Thu","Fri","Sat","Sun") -> Sat | F5: =MATCH(E5,{"Mon","Tue","Wed","Thu","Fri","Sat","Sun"}, 0) -> 6 | G5: 42899 | H5: =(DATEDIF(B5,G5,"D")) -> 31 | I5: L | J5: MNE | K5: =VLOOKUP(J5,countries,2,false) -> Montenegro | L5: =VLOOKUP($J5,countries,5,false) -> Europe | M5: =VLOOKUP($J5,countries,6,false) -> Southern Europe | N5: 2455 | O5: =VLOOKUP(N5, products, 2, FALSE) -> Clothes | P5: Online | Q5: 1171 | R5: 109.28 | S5: 35.84 | U5: =Q5*R5 -> 127966.88 | V5: =Q5*S5 -> 41968.64 | W5: =U5-V5 -> 85998.24
A6: 103435266 | B6: 41132 | C6: =YEAR(B6) -> 2012 | D6: =TEXT(B6,"MM - MMM") -> 08 - Aug | E6: =CHOOSE(WEEKDAY(B6,2),"Mon","Tue","Wed","Thu","Fri","Sat","Sun") -> Sat | F6: =MATCH(E6,{"Mon","Tue","Wed","Thu","Fri","Sat","Sun"}, 0) -> 6 | G6: 41170 | H6: =(DATEDIF(B6,G6,"D")) -> 38 | I6: H | J6: SRB | K6: =VLOOKUP(J6,countries,2,false) -> Serbia | L6: =VLOOKUP($J6,countries,5,false) -> Europe | M6: =VLOOKUP($J6,countries,6,false) -> Southern Europe | N6: 1270 | O6: =VLOOKUP(N6, products, 2, FALSE) -> Beverages | P6: Offline | Q6: 7648 | R6: 47.45 | S6: 31.79 | U6: =Q6*R6 -> 362897.6 | V6: =Q6*S6 -> 243129.92 | W6: =U6-V6 -> 119767.68
A7: 103450715 | B7: 42078 | C7: =YEAR(B7) -> 2015 | D7: =TEXT(B7,"MM - MMM") -> 03 - Mar | E7: =CHOOSE(WEEKDAY(B7,2),"Mon","Tue","Wed","Thu","Fri","Sat","Sun") -> Sun | F7: =MATCH(E7,{"Mon","Tue","Wed","Thu","Fri","Sat","Sun"}, 0) -> 7 | G7: 42112 | H7: =(DATEDIF(B7,G7,"D")) -> 34 | I7: H | J7: SVK | K7: =VLOOKUP(J7,countries,2,false) -> Slovakia | L7: =VLOOKUP($J7,countries,5,false) -> Europe | M7: =VLOOKUP($J7,countries,6,false) -> Eastern Europe | N7: 8681 | O7: =VLOOKUP(N7, products, 2, FALSE) -> Office Supplies | P7: Online | Q7: 2220 | R7: 651.21 | S7: 524.96 | U7: =Q7*R7 -> 1445686.2 | V7: =Q7*S7 -> 1165411.2 | W7: =U7-V7 -> 280275
A8: 103499639 | B8: 41384 | C8: =YEAR(B8) -> 2013 | D8: =TEXT(B8,"MM - MMM") -> 04 - Apr | E8: =CHOOSE(WEEKDAY(B8,2),"Mon","Tue","Wed","Thu","Fri","Sat","Sun") -> Sat | F8: =MATCH(E8,{"Mon","Tue","Wed","Thu","Fri","Sat","Sun"}, 0) -> 6 | G8: 41431 | H8: =(DATEDIF(B8,G8,"D")) -> 47 | I8: L | J8: FRA | K8: =VLOOKUP(J8,countries,2,false) -> France | L8: =VLOOKUP($J8,countries,5,false) -> Europe | M8: =VLOOKUP($J8,countries,6,false) -> Western Europe | N8: 4594 | O8: =VLOOKUP(N8, products, 2, FALSE) -> Fruits | P8: Online | Q8: 6698 | R8: 9.33 | S8: 6.92 | U8: =Q8*R8 -> 62492.34 | V8: =Q8*S8 -> 46350.16 | W8: =U8-V8 -> 16142.18
A9: 103762280 | B9: 40859 | C9: =YEAR(B9) -> 2011 | D9: =TEXT(B9,"MM - MMM") -> 11 - Nov | E9: =CHOOSE(WEEKDAY(B9,2),"Mon","Tue","Wed","Thu","Fri","Sat","Sun") -> Sat | F9: =MATCH(E9,{"Mon","Tue","Wed","Thu","Fri","Sat","Sun"}, 0) -> 6 | G9: 40891 | H9: =(DATEDIF(B9,G9,"D")) -> 32 | I9: M | J9: ESP | K9: =VLOOKUP(J9,countries,2,false) -> Spain | L9: =VLOOKUP($J9,countries,5,false) -> Europe | M9: =VLOOKUP($J9,countries,6,false) -> Southern Europe | N9: 5988 | O9: =VLOOKUP(N9, products, 2, FALSE) -> Vegetables | P9: Online | Q9: 4419 | R9: 154.06 | S9: 90.93 | U9: =Q9*R9 -> 680791.14 | V9: =Q9*S9 -> 401819.67 | W9: =U9-V9 -> 278971.47
A10: 103832662 | B10: 41171 | C10: =YEAR(B10) -> 2012 | D10: =TEXT(B10,"MM - MMM") -> 09 - Sep | E10: =CHOOSE(WEEKDAY(B10,2),"Mon","Tue","Wed","Thu","Fri","Sat","Sun") -> Wed | F10: =MATCH(E10,{"Mon","Tue","Wed","Thu","Fri","Sat","Sun"}, 0) -> 3 | G10: 41202 | H10: =(DATEDIF(B10,G10,"D")) -> 31 | I10: H | J10: HRV | K10: =VLOOKUP(J10,countries,2,false) -> Croatia | L10: =VLOOKUP($J10,countries,5,false) -> Europe | M10: =VLOOKUP($J10,countries,6,false) -> Southern Europe | N10: 7331 | O10: =VLOOKUP(N10, products, 2, FALSE) -> Baby Food | P10: Offline | Q10: 5247 | R10: 255.28 | S10: 159.42 | U10: =Q10*R10 -> 1339454.2 | V10: =Q10*S10 -> 836476.74 | W10: =U10-V10 -> 502977.42
A11: 104008615 | B11: 40566 | C11: =YEAR(B11) -> 2011 | D11: =TEXT(B11,"MM - MMM") -> 01 - Jan | E11: =CHOOSE(WEEKDAY(B11,2),"Mon","Tue","Wed","Thu","Fri","Sat","Sun") -> Sun | F11: =MATCH(E11,{"Mon","Tue","Wed","Thu","Fri","Sat","Sun"}, 0) -> 7 | G11: 40596 | H11: =(DATEDIF(B11,G11,"D")) -> 30 | I11: M | J11: DEU | K11: =VLOOKUP(J11,countries,2,false) -> Germany | L11: =VLOOKUP($J11,countries,5,false) -> Europe | M11: =VLOOKUP($J11,countries,6,false) -> Western Europe | N11: 2103 | O11: =VLOOKUP(N11, products, 2, FALSE) -> Cereal | P11: Online | Q11: 7315 | R11: 205.7 | S11: 117.11 | U11: =Q11*R11 -> 1504695.5 | V11: =Q11*S11 -> 856659.65 | W11: =U11-V11 -> 648035.85
A12: 104165685 | B12: 40958 | C12: =YEAR(B12) -> 2012 | D12: =TEXT(B12,"MM - MMM") -> 02 - Feb | E12: =CHOOSE(WEEKDAY(B12,2),"Mon","Tue","Wed","Thu","Fri","Sat","Sun") -> Sun | F12: =MATCH(E12,{"Mon","Tue","Wed","Thu","Fri","Sat","Sun"}, 0) -> 7 | G12: 40974 | H12: =(DATEDIF(B12,G12,"D")) -> 16 | I12: L | J12: ARM | K12: =VLOOKUP(J12,countries,2,false) -> Armenia | L12: =VLOOKUP($J12,countries,5,false) -> Asia | M12: =VLOOKUP($J12,countries,6,false) -> Western Asia | N12: 7940 | O12: =VLOOKUP(N12, products, 2, FALSE) -> Household | P12: Online | Q12: 3796 | R12: 668.27 | S12: 502.54 | U12: =Q12*R12 -> 2536752.9 | V12: =Q12*S12 -> 1907641.8 | W12: =U12-V12 -> 629111.08
A13: 104190576 | B13: 42788 | C13: =YEAR(B13) -> 2017 | D13: =TEXT(B13,"MM - MMM") -> 02 - Feb | E13: =CHOOSE(WEEKDAY(B13,2),"Mon","Tue","Wed","Thu","Fri","Sat","Sun") -> Wed | F13: =MATCH(E13,{"Mon","Tue","Wed","Thu","Fri","Sat","Sun"}, 0) -> 3 | G13: 42806 | H13: =(DATEDIF(B13,G13,"D")) -> 18 | I13: C | J13: GEO | K13: =VLOOKUP(J13,countries,2,false) -> Georgia | L13: =VLOOKUP($J13,countries,5,false) -> Asia | M13: =VLOOKUP($J13,countries,6,false) -> Western Asia | N13: 8875 | O13: =VLOOKUP(N13, products, 2, FALSE) -> Meat | P13: Offline | Q13: 1162 | R13: 421.89 | S13: 364.69 | U13: =Q13*R13 -> 490236.18 | V13: =Q13*S13 -> 423769.78 | W13: =U13-V13 -> 66466.4
A14: 104245078 | B14: 41360 | C14: =YEAR(B14) -> 2013 | D14: =TEXT(B14,"MM - MMM") -> 03 - Mar | E14: =CHOOSE(WEEKDAY(B14,2),"Mon","Tue","Wed","Thu","Fri","Sat","Sun") -> Wed | F14: =MATCH(E14,{"Mon","Tue","Wed","Thu","Fri","Sat","Sun"}, 0) -> 3 | G14: 41385 | H14: =(DATEDIF(B14,G14,"D")) -> 25 | I14: M | J14: GBR | K14: =VLOOKUP(J14,countries,2,false) -> United Kingdom | L14: =VLOOKUP($J14,countries,5,false) -> Europe | M14: =VLOOKUP($J14,countries,6,false) -> Northern Europe | N14: 4594 | O14: =VLOOKUP(N14, products, 2, FALSE) -> Fruits | P14: Offline | Q14: 7290 | R14: 9.33 | S14: 6.92 | U14: =Q14*R14 -> 68015.7 | V14: =Q14*S14 -> 50446.8 | W14: =U14-V14 -> 17568.9
A15: 104548490 | B15: 41640 | C15: =YEAR(B15) -> 2014 | D15: =TEXT(B15,"MM - MMM") -> 01 - Jan | E15: =CHOOSE(WEEKDAY(B15,2),"Mon","Tue","Wed","Thu","Fri","Sat","Sun") -> Wed | F15: =MATCH(E15,{"Mon","Tue","Wed","Thu","Fri","Sat","Sun"}, 0) -> 3 | G15: 41644 | H15: =(DATEDIF(B15,G15,"D")) -> 4 | I15: M | J15: Unknown | K15: Unknown | L15: Unknown | M15: Unknown | N15: 7331 | O15: =VLOOKUP(N15, products, 2, FALSE) -> Baby Food | P15: Online | Q15: 7076 | R15: 255.28 | S15: 159.42 | U15: =Q15*R15 -> 1806361.3 | V15: =Q15*S15 -> 1128055.9 | W15: =U15-V15 -> 678305.36
A16: 105030000 | B16: 42523 | C16: =YEAR(B16) -> 2016 | D16: =TEXT(B16,"MM - MMM") -> 06 - Jun | E16: =CHOOSE(WEEKDAY(B16,2),"Mon","Tue","Wed","Thu","Fri","Sat","Sun") -> Thu | F16: =MATCH(E16,{"Mon","Tue","Wed","Thu","Fri","Sat","Sun"}, 0) -> 4 | G16: 42534 | H16: =(DATEDIF(B16,G16,"D")) -> 11 | I16: C | J16: SVN | K16: =VLOOKUP(J16,countries,2,false) -> Slovenia | L16: =VLOOKUP($J16,countries,5,false) -> Europe | M16: =VLOOKUP($J16,countries,6,false) -> Southern Europe | N16: 2455 | O16: =VLOOKUP(N16, products, 2, FALSE) -> Clothes | P16: Offline | Q16: 9566 | R16: 109.28 | S16: 35.84 | U16: =Q16*R16 -> 1045372.5 | V16: =Q16*S16 -> 342845.44 | W16: =U16-V16 -> 702527.04
A17: 107651269 | B17: 41575 | C17: =YEAR(B17) -> 2013 | D17: =TEXT(B17,"MM - MMM") -> 10 - Oct | E17: =CHOOSE(WEEKDAY(B17,2),"Mon","Tue","Wed","Thu","Fri","Sat","Sun") -> Mon | F17: =MATCH(E17,{"Mon","Tue","Wed","Thu","Fri","Sat","Sun"}, 0) -> 1 | G17: 41589 | H17: =(DATEDIF(B17,G17,"D")) -> 14 | I17: M | J17: HRV | K17: =VLOOKUP(J17,countries,2,false) -> Croatia | L17: =VLOOKUP($J17,countries,5,false) -> Europe | M17: =VLOOKUP($J17,countries,6,false) -> Southern Europe | N17: 7940 | O17: =VLOOKUP(N17, products, 2, FALSE) -> Household | P17: Online | Q17: 5258 | R17: 668.27 | S17: 502.54 | U17: =Q17*R17 -> 3513763.7 | V17: =Q17*S17 -> 2642355.3 | W17: =U17-V17 -> 871408.34
A18: 108407437 | B18: 42054 | C18: =YEAR(B18) -> 2015 | D18: =TEXT(B18,"MM - MMM") -> 02 - Feb | E18: =CHOOSE(WEEKDAY(B18,2),"Mon","Tue","Wed","Thu","Fri","Sat","Sun") -> Thu | F18: =MATCH(E18,{"Mon","Tue","Wed","Thu","Fri","Sat","Sun"}, 0) -> 4 | G18: 42090 | H18: =(DATEDIF(B18,G18,"D")) -> 36 | I18: C | J18: ROU | K18: =VLOOKUP(J18,countries,2,false) -> Romania | L18: =VLOOKUP($J18,countries,5,false) -> Europe | M18: =VLOOKUP($J18,countries,6,false) -> Eastern Europe | N18: 7331 | O18: =VLOOKUP(N18, products, 2, FALSE) -> Baby Food | P18: Offline | Q18: 9025 | R18: 255.28 | S18: 159.42 | U18: =Q18*R18 -> 2303902 | V18: =Q18*S18 -> 1438765.5 | W18: =U18-V18 -> 865136.5
A19: 109914195 | B19: 40980 | C19: =YEAR(B19) -> 2012 | D19: =TEXT(B19,"MM - MMM") -> 03 - Mar | E19: =CHOOSE(WEEKDAY(B19,2),"Mon","Tue","Wed","Thu","Fri","Sat","Sun") -> Mon | F19: =MATCH(E19,{"Mon","Tue","Wed","Thu","Fri","Sat","Sun"}, 0) -> 1 | G19: 41015 | H19: =(DATEDIF(B19,G19,"D")) -> 35 | I19: M | J19: POL | K19: =VLOOKUP(J19,countries,2,false) -> Poland | L19: =VLOOKUP($J19,countries,5,false) -> Europe | M19: =VLOOKUP($J19,countries,6,false) -> Eastern Europe | N19: 2455 | O19: =VLOOKUP(N19, products, 2, FALSE) -> Clothes | P19: Offline | Q19: 4908 | R19: 109.28 | S19: 35.84 | U19: =Q19*R19 -> 536346.24 | V19: =Q19*S19 -> 175902.72 | W19: =U19-V19 -> 360443.52
A20: 111063039 | B20: 41055 | C20: =YEAR(B20) -> 2012 | D20: =TEXT(B20,"MM - MMM") -> 05 - May | E20: =CHOOSE(WEEKDAY(B20,2),"Mon","Tue","Wed","Thu","Fri","Sat","Sun") -> Sat | F20: =MATCH(E20,{"Mon","Tue","Wed","Thu","Fri","Sat","Sun"}, 0) -> 6 | G20: 41103 | H20: =(DATEDIF(B20,G20,"D")) -> 48 | I20: L | J20: LUX | K20: =VLOOKUP(J20,countries,2,false) -> Luxembourg | L20: =VLOOKUP($J20,countries,5,false) -> Europe | M20: =VLOOKUP($J20,countries,6,false) -> Western Europe | N20: 7331 | O20: =VLOOKUP(N20, products, 2, FALSE) -> Baby Food | P20: Online | Q20: 4876 | R20: 255.28 | S20: 159.42 | U20: =Q20*R20 -> 1244745.3 | V20: =Q20*S20 -> 777331.92 | W20: =U20-V20 -> 467413.36
A21: 111246287 | B21: 42895 | C21: =YEAR(B21) -> 2017 | D21: =TEXT(B21,"MM - MMM") -> 06 - Jun | E21: =CHOOSE(WEEKDAY(B21,2),"Mon","Tue","Wed","Thu","Fri","Sat","Sun") -> Fri | F21: =MATCH(E21,{"Mon","Tue","Wed","Thu","Fri","Sat","Sun"}, 0) -> 5 | G21: 42918 | H21: =(DATEDIF(B21,G21,"D")) -> 23 | I21: M | J21: CYP | K21: =VLOOKUP(J21,countries,2,false) -> Cyprus | L21: =VLOOKUP($J21,countries,5,false) -> Asia | M21: =VLOOKUP($J21,countries,6,false) -> Western Asia | N21: 8875 | O21: =VLOOKUP(N21, products, 2, FALSE) -> Meat | P21: Offline | Q21: 9103 | R21: 421.89 | S21: 364.69 | U21: =Q21*R21 -> 3840464.7 | V21: =Q21*S21 -> 3319773.1 | W21: =U21-V21 -> 520691.6
A22: 111496055 | B22: 40661 | C22: =YEAR(B22) -> 2011 | D22: =TEXT(B22,"MM - MMM") -> 04 - Apr | E22: =CHOOSE(WEEKDAY(B22,2),"Mon","Tue","Wed","Thu","Fri","Sat","Sun") -> Thu | F22: =MATCH(E22,{"Mon","Tue","Wed","Thu","Fri","Sat","Sun"}, 0) -> 4 | G22: 40698 | H22: =(DATEDIF(B22,G22,"D")) -> 37 | I22: M | J22: BEL | K22: =VLOOKUP(J22,countries,2,false) -> Belgium | L22: =VLOOKUP($J22,countries,5,false) -> Europe | M22: =VLOOKUP($J22,countries,6,false) -> Western Europe | N22: 4594 | O22: =VLOOKUP(N22, products, 2, FALSE) -> Fruits | P22: Online | Q22: 3015 | R22: 9.33 | S22: 6.92 | U22: =Q22*R22 -> 28129.95 | V22: =Q22*S22 -> 20863.8 | W22: =U22-V22 -> 7266.15
A23: 111893022 | B23: 42671 | C23: =YEAR(B23) -> 2016 | D23: =TEXT(B23,"MM - MMM") -> 10 - Oct | E23: =CHOOSE(WEEKDAY(B23,2),"Mon","Tue","Wed","Thu","Fri","Sat","Sun") -> Fri | F23: =MATCH(E23,{"Mon","Tue","Wed","Thu","Fri","Sat","Sun"}, 0) -> 5 | G23: 42706 | H23: =(DATEDIF(B23,G23,"D")) -> 35 | I23: L | J23: SVN | K23: =VLOOKUP(J23,countries,2,false) -> Slovenia | L23: =VLOOKUP($J23,countries,5,false) -> Europe | M23: =VLOOKUP($J23,countries,6,false) -> Southern Europe | N23: 7331 | O23: =VLOOKUP(N23, products, 2, FALSE) -> Baby Food | P23: Online | Q23: 486 | R23: 255.28 | S23: 159.42 | U23: =Q23*R23 -> 124066.08 | V23: =Q23*S23 -> 77478.12 | W23: =U23-V23 -> 46587.96
A24: 112330758 | B24: 42719 | C24: =YEAR(B24) -> 2016 | D24: =TEXT(B24,"MM - MMM") -> 12 - Dec | E24: =CHOOSE(WEEKDAY(B24,2),"Mon","Tue","Wed","Thu","Fri","Sat","Sun") -> Thu | F24: =MATCH(E24,{"Mon","Tue","Wed","Thu","Fri","Sat","Sun"}, 0) -> 4 | G24: 42746 | H24: =(DATEDIF(B24,G24,"D")) -> 27 | I24: C | J24: LTU | K24: =VLOOKUP(J24,countries,2,false) -> Lithuania | L24: =VLOOKUP($J24,countries,5,false) -> Europe | M24: =VLOOKUP($J24,countries,6,false) -> Northern Europe | N24: 8681 | O24: =VLOOKUP(N24, products, 2, FALSE) -> Office Supplies | P24: Offline | Q24: 22 | R24: 651.21 | S24: 524.96 | U24: =Q24*R24 -> 14326.62 | V24: =Q24*S24 -> 11549.12 | W24: =U24-V24 -> 2777.5
A25: 113524663 | B25: 40480 | C25: =YEAR(B25) -> 2010 | D25: =TEXT(B25,"MM - MMM") -> 10 - Oct | E25: =CHOOSE(WEEKDAY(B25,2),"Mon","Tue","Wed","Thu","Fri","Sat","Sun") -> Fri | F25: =MATCH(E25,{"Mon","Tue","Wed","Thu","Fri","Sat","Sun"}, 0) -> 5 | G25: 40521 | H25: =(DATEDIF(B25,G25,"D")) -> 41 | I25: L | J25: RUS | K25: =VLOOKUP(J25,countries,2,false) -> Russia | L25: =VLOOKUP($J25,countries,5,false) -> Europe | M25: =VLOOKUP($J25,countries,6,false) -> Eastern Europe | N25: 8293 | O25: =VLOOKUP(N25, products, 2, FALSE) -> Cosmetics | P25: Online | Q25: 3325 | R25: 437.2 | S25: 263.33 | U25: =Q25*R25 -> 1453690 | V25: =Q25*S25 -> 875572.25 | W25: =U25-V25 -> 578117.75
A26: 114954173 | B26: 40212 | C26: =YEAR(B26) -> 2010 | D26: =TEXT(B26,"MM - MMM") -> 02 - Feb | E26: =CHOOSE(WEEKDAY(B26,2),"Mon","Tue","Wed","Thu","Fri","Sat","Sun") -> Wed | F26: =MATCH(E26,{"Mon","Tue","Wed","Thu","Fri","Sat","Sun"}, 0) -> 3 | G26: 40220 | H26: =(DATEDIF(B26,G26,"D")) -> 8 | I26: C | J26: MLT | K26: =VLOOKUP(J26,countries,2,false) -> Malta | L26: =VLOOKUP($J26,countries,5,false) -> Europe | M26: =VLOOKUP($J26,countries,6,false) -> Southern Europe | N26: 4594 | O26: =VLOOKUP(N26, products, 2, FALSE) -> Fruits | P26: Offline | Q26: 6349 | R26: 9.33 | S26: 6.92 | U26: =Q26*R26 -> 59236.17 | V26: =Q26*S26 -> 43935.08 | W26: =U26-V26 -> 15301.09
A27: 115363156 | B27: 42342 | C27: =YEAR(B27) -> 2015 | D27: =TEXT(B27,"MM - MMM") -> 12 - Dec | E27: =CHOOSE(WEEKDAY(B27,2),"Mon","Tue","Wed","Thu","Fri","Sat","Sun") -> Fri | F27: =MATCH(E27,{"Mon","Tue","Wed","Thu","Fri","Sat","Sun"}, 0) -> 5 | G27: 42379 | H27: =(DATEDIF(B27,G27,"D")) -> 37 | I27: H | J27: UKR | K27: =VLOOKUP(J27,countries,2,false) -> Ukraine | L27: =VLOOKUP($J27,countries,5,false) -> Europe | M27: =VLOOKUP($J27,countries,6,false) -> Eastern Europe | N27: 8681 | O27: =VLOOKUP(N27, products, 2, FALSE) -> Office Supplies | P27: Offline | Q27: 7376 | R27: 651.21 | S27: 524.96 | U27: =Q27*R27 -> 4803325 | V27: =Q27*S27 -> 3872105 | W27: =U27-V27 -> 931220
A28: 117929494 | B28: 42028 | C28: =YEAR(B28) -> 2015 | D28: =TEXT(B28,"MM - MMM") -> 01 - Jan | E28: =CHOOSE(WEEKDAY(B28,2),"Mon","Tue","Wed","Thu","Fri","Sat","Sun") -> Sat | F28: =MATCH(E28,{"Mon","Tue","Wed","Thu","Fri","Sat","Sun"}, 0) -> 6 | G28: 42065 | H28: =(DATEDIF(B28,G28,"D")) -> 37 | I28: H | J28: Unknown | K28: Unknown | L28: Unknown | M28: Unknown | N28: 4594 | O28: =VLOOKUP(N28, products, 2, FALSE) -> Fruits | P28: Offline | Q28: 6813 | R28: 9.33 | S28: 6.92 | U28: =Q28*R28 -> 63565.29 | V28: =Q28*S28 -> 47145.96 | W28: =U28-V28 -> 16419.33
A29: 118086564 | B29: 42419 | C29: =YEAR(B29) -> 2016 | D29: =TEXT(B29,"MM - MMM") -> 02 - Feb | E29: =CHOOSE(WEEKDAY(B29,2),"Mon","Tue","Wed","Thu","Fri","Sat","Sun") -> Fri | F29: =MATCH(E29,{"Mon","Tue","Wed","Thu","Fri","Sat","Sun"}, 0) -> 5 | G29: 42442 | H29: =(DATEDIF(B29,G29,"D")) -> 23 | I29: M | J29: NOR | K29: =VLOOKUP(J29,countries,2,false) -> Norway | L29: =VLOOKUP($J29,countries,5,false) -> Europe | M29: =VLOOKUP($J29,countries,6,false) -> Northern Europe | N29: 8969 | O29: =VLOOKUP(N29, products, 2, FALSE) -> Snacks | P29: Online | Q29: 3293 | R29: 152.58 | S29: 97.44 | U29: =Q29*R29 -> 502445.94 | V29: =Q29*S29 -> 320869.92 | W29: =U29-V29 -> 181576.02
A30: 118659913 | B30: 41853 | C30: =YEAR(B30) -> 2014 | D30: =TEXT(B30,"MM - MMM") -> 08 - Aug | E30: =CHOOSE(WEEKDAY(B30,2),"Mon","Tue","Wed","Thu","Fri","Sat","Sun") -> Sat | F30: =MATCH(E30,{"Mon","Tue","Wed","Thu","Fri","Sat","Sun"}, 0) -> 6 | G30: 41868 | H30: =(DATEDIF(B30,G30,"D")) -> 15 | I30: C | J30: CZE | K30: =VLOOKUP(J30,countries,2,false) -> Czech Republic | L30: =VLOOKUP($J30,countries,5,false) -> Europe | M30: =VLOOKUP($J30,countries,6,false) -> Eastern Europe | N30: 2103 | O30: =VLOOKUP(N30, products, 2, FALSE) -> Cereal | P30: Online | Q30: 2960 | R30: 205.7 | S30: 117.11 | U30: =Q30*R30 -> 608872 | V30: =Q30*S30 -> 346645.6 | W30: =U30-V30 -> 262226.4
A31: 118859469 | B31: 40696 | C31: =YEAR(B31) -> 2011 | D31: =TEXT(B31,"MM - MMM") -> 06 - Jun | E31: =CHOOSE(WEEKDAY(B31,2),"Mon","Tue","Wed","Thu","Fri","Sat","Sun") -> Thu | F31: =MATCH(E31,{"Mon","Tue","Wed","Thu","Fri","Sat","Sun"}, 0) -> 4 | G31: 40725 | H31: =(DATEDIF(B31,G31,"D")) -> 29 | I31: L | J31: Unknown | K31: Unknown | L31: Unknown | M31: Unknown | N31: 8969 | O31: =VLOOKUP(N31, products, 2, FALSE) -> Snacks | P31: Offline | Q31: 2013 | R31: 152.58 | S31: 97.44 | U31: =Q31*R31 -> 307143.54 | V31: =Q31*S31 -> 196146.72 | W31: =U31-V31 -> 110996.82
A32: 119935786 | B32: 42018 | C32: =YEAR(B32) -> 2015 | D32: =TEXT(B32,"MM - MMM") -> 01 - Jan | E32: =CHOOSE(WEEKDAY(B32,2),"Mon","Tue","Wed","Thu","Fri","Sat","Sun") -> Wed | F32: =MATCH(E32,{"Mon","Tue","Wed","Thu","Fri","Sat","Sun"}, 0) -> 3 | G32: 42031 | H32: =(DATEDIF(B32,G32,"D")) -> 13 | I32: L | J32: ROU | K32: =VLOOKUP(J32,countries,2,false) -> Romania | L32: =VLOOKUP($J32,countries,5,false) -> Europe | M32: =VLOOKUP($J32,countries,6,false) -> Eastern Europe | N32: 3127 | O32: =VLOOKUP(N32, products, 2, FALSE) -> Personal Care | P32: Offline | Q32: 519 | R32: 81.73 | S32: 56.67 | U32: =Q32*R32 -> 42417.87 | V32: =Q32*S32 -> 29411.73 | W32: =U32-V32 -> 13006.14
A33: 120419871 | B33: 42137 | C33: =YEAR(B33) -> 2015 | D33: =TEXT(B33,"MM - MMM") -> 05 - May | E33: =CHOOSE(WEEKDAY(B33,2),"Mon","Tue","Wed","Thu","Fri","Sat","Sun") -> Wed | F33: =MATCH(E33,{"Mon","Tue","Wed","Thu","Fri","Sat","Sun"}, 0) -> 3 | G33: 42181 | H33: =(DATEDIF(B33,G33,"D")) -> 44 | I33: H | J33: LTU | K33: =VLOOKUP(J33,countries,2,false) -> Lithuania | L33: =VLOOKUP($J33,countries,5,false) -> Europe | M33: =VLOOKUP($J33,countries,6,false) -> Northern Europe | N33: 3127 | O33: =VLOOKUP(N33, products, 2, FALSE) -> Personal Care | P33: Online | Q33: 3771 | R33: 81.73 | S33: 56.67 | U33: =Q33*R33 -> 308203.83 | V33: =Q33*S33 -> 213702.57 | W33: =U33-V33 -> 94501.26
A34: 120977771 | B34: 40625 | C34: =YEAR(B34) -> 2011 | D34: =TEXT(B34,"MM - MMM") -> 03 - Mar | E34: =CHOOSE(WEEKDAY(B34,2),"Mon","Tue","Wed","Thu","Fri","Sat","Sun") -> Wed | F34: =MATCH(E34,{"Mon","Tue","Wed","Thu","Fri","Sat","Sun"}, 0) -> 3 | G34: 40665 | H34: =(DATEDIF(B34,G34,"D")) -> 40 | I34: M | J34: ARM | K34: =VLOOKUP(J34,countries,2,false) -> Armenia | L34: =VLOOKUP($J34,countries,5,false) -> Asia | M34: =VLOOKUP($J34,countries,6,false) -> Western Asia | N34: 4594 | O34: =VLOOKUP(N34, products, 2, FALSE) -> Fruits | P34: Online | Q34: 8866 | R34: 9.33 | S34: 6.92 | U34: =Q34*R34 -> 82719.78 | V34: =Q34*S34 -> 61352.72 | W34: =U34-V34 -> 21367.06
A35: 121380746 | B35: 42695 | C35: =YEAR(B35) -> 2016 | D35: =TEXT(B35,"MM - MMM") -> 11 - Nov | E35: =CHOOSE(WEEKDAY(B35,2),"Mon","Tue","Wed","Thu","Fri","Sat","Sun") -> Mon | F35: =MATCH(E35,{"Mon","Tue","Wed","Thu","Fri","Sat","Sun"}, 0) -> 1 | G35: 42722 | H35: =(DATEDIF(B35,G35,"D")) -> 27 | I35: C | J35: MLT | K35: =VLOOKUP(J35,countries,2,false) -> Malta | L35: =VLOOKUP($J35,countries,5,false) -> Europe | M35: =VLOOKUP($J35,countries,6,false) -> Southern Europe | N35: 4594 | O35: =VLOOKUP(N35, products, 2, FALSE) -> Fruits | P35: Online | Q35: 8115 | R35: 9.33 | S35: 6.92 | U35: =Q35*R35 -> 75712.95 | V35: =Q35*S35 -> 56155.8 | W35: =U35-V35 -> 19557.15
A36: 121945512 | B36: 42833 | C36: =YEAR(B36) -> 2017 | D36: =TEXT(B36,"MM - MMM") -> 04 - Apr | E36: =CHOOSE(WEEKDAY(B36,2),"Mon","Tue","Wed","Thu","Fri","Sat","Sun") -> Sat | F36: =MATCH(E36,{"Mon","Tue","Wed","Thu","Fri","Sat","Sun"}, 0) -> 6 | G36: 42837 | H36: =(DATEDIF(B36,G36,"D")) -> 4 | I36: C | J36: GBR | K36: =VLOOKUP(J36,countries,2,false) -> United Kingdom | L36: =VLOOKUP($J36,countries,5,false) -> Europe | M36: =VLOOKUP($J36,countries,6,false) -> Northern Europe | N36: 1270 | O36: =VLOOKUP(N36, products, 2, FALSE) -> Beverages | P36: Online | Q36: 5242 | R36: 47.45 | S36: 31.79 | U36: =Q36*R36 -> 248732.9 | V36: =Q36*S36 -> 166643.18 | W36: =U36-V36 -> 82089.72
A37: 122144210 | B37: 42852 | C37: =YEAR(B37) -> 2017 | D37: =TEXT(B37,"MM - MMM") -> 04 - Apr | E37: =CHOOSE(WEEKDAY(B37,2),"Mon","Tue","Wed","Thu","Fri","Sat","Sun") -> Thu | F37: =MATCH(E37,{"Mon","Tue","Wed","Thu","Fri","Sat","Sun"}, 0) -> 4 | G37: 42879 | H37: =(DATEDIF(B37,G37,"D")) -> 27 | I37: C | J37: MNE | K37: =VLOOKUP(J37,countries,2,false) -> Montenegro | L37: =VLOOKUP($J37,countries,5,false) -> Europe | M37: =VLOOKUP($J37,countries,6,false) -> Southern Europe | N37: 1270 | O37: =VLOOKUP(N37, products, 2, FALSE) -> Beverages | P37: Offline | Q37: 4041 | R37: 47.45 | S37: 31.79 | U37: =Q37*R37 -> 191745.45 | V37: =Q37*S37 -> 128463.39 | W37: =U37-V37 -> 63282.06
A38: 122372519 | B38: 42379 | C38: =YEAR(B38) -> 2016 | D38: =TEXT(B38,"MM - MMM") -> 01 - Jan | E38: =CHOOSE(WEEKDAY(B38,2),"Mon","Tue","Wed","Thu","Fri","Sat","Sun") -> Sun | F38: =MATCH(E38,{"Mon","Tue","Wed","Thu","Fri","Sat","Sun"}, 0) -> 7 | G38: 42382 | H38: =(DATEDIF(B38,G38,"D")) -> 3 | I38: L | J38: PRT | K38: =VLOOKUP(J38,countries,2,false) -> Portugal | L38: =VLOOKUP($J38,countries,5,false) -> Europe | M38: =VLOOKUP($J38,countries,6,false) -> Southern Europe | N38: 1270 | O38: =VLOOKUP(N38, products, 2, FALSE) -> Beverages | P38: Offline | Q38: 1603 | R38: 47.45 | S38: 31.79 | U38: =Q38*R38 -> 76062.35 | V38: =Q38*S38 -> 50959.37 | W38: =U38-V38 -> 25102.98
A39: 122967326 | B39: 42818 | C39: =YEAR(B39) -> 2017 | D39: =TEXT(B39,"MM - MMM") -> 03 - Mar | E39: =CHOOSE(WEEKDAY(B39,2),"Mon","Tue","Wed","Thu","Fri","Sat","Sun") -> Fri | F39: =MATCH(E39,{"Mon","Tue","Wed","Thu","Fri","Sat","Sun"}, 0) -> 5 | G39: 42850 | H39: =(DATEDIF(B39,G39,"D")) -> 32 | I39: H | J39: BLR | K39: =VLOOKUP(J39,countries,2,false) -> Belarus | L39: =VLOOKUP($J39,countries,5,false) -> Europe | M39: =VLOOKUP($J39,countries,6,false) -> Eastern Europe | N39: 1270 | O39: =VLOOKUP(N39, products, 2, FALSE) -> Beverages | P39: Online | Q39: 7619 | R39: 47.45 | S39: 31.79 | U39: =Q39*R39 -> 361521.55 | V39: =Q39*S39 -> 242208.01 | W39: =U39-V39 -> 119313.54
A40: 123086202 | B40: 41641 | C40: =YEAR(B40) -> 2014 | D40: =TEXT(B40,"MM - MMM") -> 01 - Jan | E40: =CHOOSE(WEEKDAY(B40,2),"Mon","Tue","Wed","Thu","Fri","Sat","Sun") -> Thu | F40: =MATCH(E40,{"Mon","Tue","Wed","Thu","Fri","Sat","Sun"}, 0) -> 4 | G40: 41690 | H40: =(DATEDIF(B40,G40,"D")) -> 49 | I40: M | J40: EST | K40: =VLOOKUP(J40,countries,2,false) -> Estonia | L40: =VLOOKUP($J40,countries,5,false) -> Europe | M40: =VLOOKUP($J40,countries,6,false) -> Northern Europe | N40: 7331 | O40: =VLOOKUP(N40, products, 2, FALSE) -> Baby Food | P40: Offline | Q40: 2797 | R40: 255.28 | S40: 159.42 | U40: =Q40*R40 -> 714018.16 | V40: =Q40*S40 -> 445897.74 | W40: =U40-V40 -> 268120.42
...

Sheet products
A1: id | B1: item_type
A2: 2103 | B2: Cereal
A3: 7940 | B3: Household
A4: 2455 | B4: Clothes
A5: 1270 | B5: Beverages
A6: 8681 | B6: Office Supplies
A7: 4594 | B7: Fruits
A8: 5988 | B8: Vegetables
A9: 7331 | B9: Baby Food
A10: 8875 | B10: Meat
A11: 8293 | B11: Cosmetics
A12: 8969 | B12: Snacks
A13: 3127 | B13: Personal Care

Sheet 4.Metrics
A1: Total number of orders | B1: =COUNTA(events!A2:A1000) -> 1330
A2: Total profit | B2: =SUM(events!W2:W1000) -> 501434459
A3: Total number of contries | B3: =IFERROR(__xludf.DUMMYFUNCTION("COUNTUNIQUE(events!J2:J1000)"),46.0) -> 46
A4: Total revenue | B4: =SUM(events!U2:U1000) -> 1702129408

Sheet 5.Analysis of products
A1: id | B1: item_type | C1: Orders count | E1: id | F1: item_type | G1: revenue | I1: id | J1: item_type | K1: cost | M1: id | N1: item_type | O1: profit
A2: 8681 | B2: Office Supplies | C2: =COUNTIF(product_id, A2) -> 123 | E2: 8681 | F2: Office Supplies | G2: =SUMIF(product_id, E2, total_revenue) -> 4.02214e+08 | I2: 8681 | J2: Office Supplies | K2: =SUMIF(product_id,I2, total_cost) -> 3.2423682e+08 | M2: 8293 | N2: Cosmetics | O2: =SUMIF(product_id, M2, total_profit) -> 92723306
A3: 1270 | B3: Beverages | C3: =COUNTIF(product_id, A3) -> 121 | E3: 7940 | F3: Household | G3: =SUMIF(product_id, E3, total_revenue) -> 2.942052e+08 | I3: 7940 | J3: Household | K3: =SUMIF(product_id,I3, total_cost) -> 2.2124273e+08 | M3: 8681 | N3: Office Supplies | O3: =SUMIF(product_id, M3, total_profit) -> 77977176
A4: 3127 | B4: Personal Care | C4: =COUNTIF(product_id, A4) -> 115 | E4: 8293 | F4: Cosmetics | G4: =SUMIF(product_id, E4, total_revenue) -> 2.3315483e+08 | I4: 8875 | J4: Meat | K4: =SUMIF(product_id,I4, total_cost) -> 1.9342428e+08 | M4: 7940 | N4: Household | O4: =SUMIF(product_id, M4, total_profit) -> 72962467
A5: 8293 | B5: Cosmetics | C5: =COUNTIF(product_id, A5) -> 114 | E5: 8875 | F5: Meat | G5: =SUMIF(product_id, E5, total_revenue) -> 2.2376202e+08 | I5: 8293 | J5: Cosmetics | K5: =SUMIF(product_id,I5, total_cost) -> 140431519 | M5: 7331 | N5: Baby Food | O5: =SUMIF(product_id, M5, total_profit) -> 53940997
A6: 5988 | B6: Vegetables | C6: =COUNTIF(product_id, A6) -> 114 | E6: 7331 | F6: Baby Food | G6: =SUMIF(product_id, E6, total_revenue) -> 1.4364759e+08 | I6: 7331 | J6: Baby Food | K6: =SUMIF(product_id,I6, total_cost) -> 89706591 | M6: 2455 | N6: Clothes | O6: =SUMIF(product_id, M6, total_profit) -> 43431314
A7: 7331 | B7: Baby Food | C7: =COUNTIF(product_id, A7) -> 112 | E7: 2103 | F7: Cereal | G7: =SUMIF(product_id, E7, total_revenue) -> 95791404 | I7: 2103 | J7: Cereal | K7: =SUMIF(product_id,I7, total_cost) -> 54536370 | M7: 2103 | N7: Cereal | O7: =SUMIF(product_id, M7, total_profit) -> 41255034
A8: 4594 | B8: Fruits | C8: =COUNTIF(product_id, A8) -> 112 | E8: 5988 | F8: Vegetables | G8: =SUMIF(product_id, E8, total_revenue) -> 89746729 | I8: 5988 | J8: Vegetables | K8: =SUMIF(product_id,I8, total_cost) -> 52970726 | M8: 5988 | N8: Vegetables | O8: =SUMIF(product_id, M8, total_profit) -> 36776003
A9: 8875 | B9: Meat | C9: =COUNTIF(product_id, A9) -> 111 | E9: 8969 | F9: Snacks | G9: =SUMIF(product_id, E9, total_revenue) -> 74788613 | I9: 8969 | J9: Snacks | K9: =SUMIF(product_id,I9, total_cost) -> 47761190 | M9: 8875 | N9: Meat | O9: =SUMIF(product_id, M9, total_profit) -> 30337736
A10: 2455 | B10: Clothes | C10: =COUNTIF(product_id, A10) -> 105 | E10: 2455 | F10: Clothes | G10: =SUMIF(product_id, E10, total_revenue) -> 64626553 | I10: 3127 | J10: Personal Care | K10: =SUMIF(product_id,I10, total_cost) -> 31603612 | M10: 8969 | N10: Snacks | O10: =SUMIF(product_id, M10, total_profit) -> 27027422
A11: 2103 | B11: Cereal | C11: =COUNTIF(product_id, A11) -> 103 | E11: 3127 | F11: Personal Care | G11: =SUMIF(product_id, E11, total_revenue) -> 45579023 | I11: 2455 | J11: Clothes | K11: =SUMIF(product_id,I11, total_cost) -> 21195238 | M11: 3127 | N11: Personal Care | O11: =SUMIF(product_id, M11, total_profit) -> 13975411
A12: 8969 | B12: Snacks | C12: =COUNTIF(product_id, A12) -> 103 | E12: 1270 | F12: Beverages | G12: =SUMIF(product_id, E12, total_revenue) -> 29093161 | I12: 1270 | J12: Beverages | K12: =SUMIF(product_id,I12, total_cost) -> 19491498 | M12: 1270 | N12: Beverages | O12: =SUMIF(product_id, M12, total_profit) -> 9601662.8
A13: 7940 | B13: Household | C13: =COUNTIF(product_id, A13) -> 97 | E13: 4594 | F13: Fruits | G13: =SUMIF(product_id, E13, total_revenue) -> 5520299.8 | I13: 4594 | J13: Fruits | K13: =SUMIF(product_id,I13, total_cost) -> 4094370.2 | M13: 4594 | N13: Fruits | O13: =SUMIF(product_id, M13, total_profit) -> 1425929.5

Sheet 6.1 Geo_Countries
F3: Revenue by Coutries
F24: Profit by Coutries
F46: Average Shipping Days

Sheet 6.2 Geo_Regions

Sheet 6.3 Geo_Subregions

Sheet 7.Sales channel

Sheet 8.Shipping Duration
A1: Category | B1: Median of Shipping Duration | C1: Orders count | D1: Total profit | G1: region | H1: Countries | I1: Median of Shipping Duration | J1: Orders count | K1: Total profit
A2: Cereal | B2: 29 | C2: 103 | D2: 41255034 | G2: Asia | H2: Georgia | I2: 32 | J2: 23 | K2: 5697679.2
A3: Baby Food | B3: 28.5 | C3: 112 | D3: 53940997 | H3: Armenia | I3: 24 | J3: 29 | K3: 9422353.2
A4: Cosmetics | B4: 28 | C4: 114 | D4: 92723306 | H4: Cyprus | I4: 23.5 | J4: 30 | K4: 10032221
A5: Office Supplies | B5: 27 | C5: 123 | D5: 77977176 | G5: Europe | H5: Hungary | I5: 36 | J5: 25 | K5: 13786231
A6: Snacks | B6: 25 | C6: 103 | D6: 27027422 | H6: Russia | I6: 34 | J6: 32 | K6: 13267683
A7: Meat | B7: 25 | C7: 111 | D7: 30337736 | H7: Monaco | I7: 33 | J7: 13 | K7: 4797048.8
A8: Household | B8: 24 | C8: 97 | D8: 72962467 | H8: Slovakia | I8: 32 | J8: 30 | K8: 12052790
A9: Fruits | B9: 23 | C9: 112 | D9: 1425929.5 | H9: Finland | I9: 31 | J9: 23 | K9: 7525362.8
A10: Beverages | B10: 23 | C10: 121 | D10: 9601662.8 | H10: Luxembourg | I10: 30.5 | J10: 28 | K10: 9870766.1
A11: Vegetables | B11: 21 | C11: 114 | D11: 36776003 | H11: Lithuania | I11: 30 | J11: 25 | K11: 7997297.8
A12: Clothes | B12: 21 | C12: 105 | D12: 43431314 | H12: Bosnia and Herzegovina | I12: 30 | J12: 33 | K12: 13257603
A13: Personal Care | B13: 20 | C13: 115 | D13: 13975411 | H13: Ukraine | I13: 29 | J13: 33 | K13: 14804926
H14: Montenegro | I14: 29 | J14: 28 | K14: 11169661
H15: Austria | I15: 29 | J15: 28 | K15: 10027510
H16: Belgium | I16: 28.5 | J16: 26 | K16: 7476060.1
H17: Sweden | I17: 28 | J17: 29 | K17: 11155329
H18: Czech Republic | I18: 28 | J18: 31 | K18: 13635594
H19: Switzerland | I19: 27.5 | J19: 28 | K19: 11037298
H20: Poland | I20: 27 | J20: 28 | K20: 10671101
H21: Netherlands | I21: 27 | J21: 24 | K21: 5762490.7
H22: Albania | I22: 27 | J22: 21 | K22: 10490706
H23: Belarus | I23: 26.5 | J23: 28 | K23: 11852421
H24: Bulgaria | I24: 26 | J24: 30 | K24: 10408343
H25: Andorra | I25: 26 | J25: 40 | K25: 15410037
... H46: Croatia | I46: 12.5 | J46: 18 | K46: 7318229.4
A53: Does profit depend on the shipping duration?
A54: There is no strong relationship between shipping duration and profit.
A55: Categories with both high and low shipping duration demonstrate a wide range of profitability,
A56: indicating that delivery time is not a key driver of profit.

Sheet 9.1 Sales Dynamics by Year, Mon
P20: Conclusion
P22: Sales fluctuate over time across product categories. There is no consistent yearly growth,
P23: but noticeable monthly seasonality with peaks in mid-year (months 5–7) and declines in months such as 4 and 8.

Sheet 9.2 Sales Dynamics by Year, Mon
E116: Conclusion | P116: Conclusion
E117: Europe generates the majority of profit with clear monthly fluctuations, | P117: Europe consistently generates much higher profit than Asia.
E118: while Asia shows stable but significantly lower performance. | P118: Peak performance was in 2012, followed by a gradual decline.
P119: Asia remains stable but significantly lower in profit.
P120: Asia remains stable but significantly lower in profit.
A160: No consistent seasonality observed. Profit fluctuates across months, with occasional spikes driven by specific countries. | K160: No consistent growth trend observed. Profit varies across years, with Poland showing the highest volatility.

Sheet 10.Profit by weekday

Sheet 11.Dashboard
I2: Total number of orders | J2: =COUNTA(events!A2:A1000) -> 1330
I3: Total profit | J3: =SUM(events!W2:W1000) -> 501434459
I4: Total number of contries | J4: =IFERROR(__xludf.DUMMYFUNCTION("COUNTUNIQUE(events!J2:J1000)"),46.0) -> 46
I5: Total revenue | J5: =SUM(events!U2:U1000) -> 1702129408
C8: Profit by Countries

Sheet 12.ABC Analysis
G1: ABC Analysis by Category
G2: Category | H2: Total profit | I2: % of total | J2: Cumulative % | K2: ABC
G3: Cosmetics | H3: 10833318 | I3: =H3 / SUM($H$3:$H$13) -> 0.27848864 | J3: =SUM($I$3:I3) -> 0.27848864 | K3: =IF(J3<=0.8,"A",IF(J3<=0.95,"B","C")) -> A
G4: Office Supplies | H4: 6632543.8 | I4: =H4 / SUM($H$3:$H$13) -> 0.17050068 | J4: =SUM($I$3:I4) -> 0.44898932 | K4: =IF(J4<=0.8,"A",IF(J4<=0.95,"B","C")) -> A
G5: Household | H5: 5500910.2 | I5: =H5 / SUM($H$3:$H$13) -> 0.14141014 | J5: =SUM($I$3:I5) -> 0.59039946 | K5: =IF(J5<=0.8,"A",IF(J5<=0.95,"B","C")) -> A
G6: Baby Food | H6: 4088851.6 | I6: =H6 / SUM($H$3:$H$13) -> 0.1051108 | J6: =SUM($I$3:I6) -> 0.69551026 | K6: =IF(J6<=0.8,"A",IF(J6<=0.95,"B","C")) -> A
G7: Clothes | H7: 2953663.3 | I7: =H7 / SUM($H$3:$H$13) -> 0.075928878 | J7: =SUM($I$3:I7) -> 0.77143914 | K7: =IF(J7<=0.8,"A",IF(J7<=0.95,"B","C")) -> A
G8: Cereal | H8: 2500898.4 | I8: =H8 / SUM($H$3:$H$13) -> 0.064289795 | J8: =SUM($I$3:I8) -> 0.83572893 | K8: =IF(J8<=0.8,"A",IF(J8<=0.95,"B","C")) -> B
G9: Vegetables | H9: 2204971.7 | I9: =H9 / SUM($H$3:$H$13) -> 0.056682503 | J9: =SUM($I$3:I9) -> 0.89241143 | K9: =IF(J9<=0.8,"A",IF(J9<=0.95,"B","C")) -> B
G10: Meat | H10: 1777615.2 | I10: =H10 / SUM($H$3:$H$13) -> 0.045696585 | J10: =SUM($I$3:I10) -> 0.93810802 | K10: =IF(J10<=0.8,"A",IF(J10<=0.95,"B","C")) -> B
G11: Snacks | H11: 1267739.6 | I11: =H11 / SUM($H$3:$H$13) -> 0.032589377 | J11: =SUM($I$3:I11) -> 0.9706974 | K11: =IF(J11<=0.8,"A",IF(J11<=0.95,"B","C")) -> C
G12: Personal Care | H12: 648828.46 | I12: =H12 / SUM($H$3:$H$13) -> 0.016679226 | J12: =SUM($I$3:I12) -> 0.98737662 | K12: =IF(J12<=0.8,"A",IF(J12<=0.95,"B","C")) -> C
G13: Beverages | H13: 491054.37 | I13: =H13 / SUM($H$3:$H$13) -> 0.012623378 | J13: =SUM($I$3:I13) -> 1 | K13: =IF(J13<=0.8,"A",IF(J13<=0.95,"B","C")) -> C
G14: Fruits | H14: 99296.82 | I14: =H14 / SUM($H$3:$H$13) -> 0.0025525916 | J14: =SUM($I$3:I14) -> 1.0025526 | K14: =IF(J14<=0.8,"A",IF(J14<=0.95,"B","C")) -> C

Sheet 13.ABC visualization 
A1: Category | B1: Total profit | C1: % of total | D1: Cumulative % | E1: ABC | I1: Category | J1: Total revenue | K1: % of total | L1: Cumulative % | M1: ABC | Q1: Category | R1: Profit ABC | S1: Revenue ABC | T1: Profit | U1: Revenue
A2: Cosmetics | B2: 10833318 | C2: =B2/ SUM($B$2:$B$13) -> 0.27777958 | D2: =SUM($C$2:C2) -> 0.27777958 | E2: A | I2: Office Supplies | J2: 34211317 | K2: =J2 / SUM($J$2:$J$13) -> 0.25044801 | L2: =SUM($K$2:K2) -> 0.25044801 | M2: =IF(L2<=0.8,"A",IF(L2<=0.95,"B","C")) -> A | Q2: Cosmetics | R2: =VLOOKUP(A2,$A$2:$E$13,5,FALSE) -> A | S2: =VLOOKUP(A2,$I$2:$M$13,5,FALSE) -> A | T2: =VLOOKUP(Q2,$A$2:$E$13,2,FALSE) -> 10833318 | U2: =VLOOKUP(Q2,$I$2:$M$13,2,FALSE) -> 27240620
A3: Office Supplies | B3: 6632543.8 | C3: =B3/ SUM($B$2:$B$13) -> 0.17006657 | D3: =SUM($C$2:C3) -> 0.44784615 | E3: A | I3: Cosmetics | J3: 27240620 | K3: =J3 / SUM($J$2:$J$13) -> 0.1994182 | L3: =SUM($K$2:K3) -> 0.44986621 | M3: =IF(L3<=0.8,"A",IF(L3<=0.95,"B","C")) -> A | Q3: Office Supplies | R3: =VLOOKUP(A3,$A$2:$E$13,5,FALSE) -> A | S3: =VLOOKUP(A3,$I$2:$M$13,5,FALSE) -> A | T3: =VLOOKUP(Q3,$A$2:$E$13,2,FALSE) -> 6632543.8 | U3: =VLOOKUP(Q3,$I$2:$M$13,2,FALSE) -> 34211317
A4: Household | B4: 5500910.2 | C4: =B4/ SUM($B$2:$B$13) -> 0.14105009 | D4: =SUM($C$2:C4) -> 0.58889625 | E4: A | I4: Household | J4: 22181218 | K4: =J4 / SUM($J$2:$J$13) -> 0.16238024 | L4: =SUM($K$2:K4) -> 0.61224645 | M4: =IF(L4<=0.8,"A",IF(L4<=0.95,"B","C")) -> A | Q4: Household | R4: =VLOOKUP(A4,$A$2:$E$13,5,FALSE) -> A | S4: =VLOOKUP(A4,$I$2:$M$13,5,FALSE) -> A | T4: =VLOOKUP(Q4,$A$2:$E$13,2,FALSE) -> 5500910.2 | U4: =VLOOKUP(Q4,$I$2:$M$13,2,FALSE) -> 22181218
A5: Baby Food | B5: 4088851.6 | C5: =B5/ SUM($B$2:$B$13) -> 0.10484318 | D5: =SUM($C$2:C5) -> 0.69373943 | E5: A | I5: Cereal | J5: 18445875 | K5: =J5 / SUM($J$2:$J$13) -> 0.13503522 | L5: =SUM($K$2:K5) -> 0.74728167 | M5: =IF(L5<=0.8,"A",IF(L5<=0.95,"B","C")) -> A | Q5: Baby Food | R5: =VLOOKUP(A5,$A$2:$E$13,5,FALSE) -> A | S5: =VLOOKUP(A5,$I$2:$M$13,5,FALSE) -> B | T5: =VLOOKUP(Q5,$A$2:$E$13,2,FALSE) -> 4088851.6 | U5: =VLOOKUP(Q5,$I$2:$M$13,2,FALSE) -> 11314417
A6: Clothes | B6: 2953663.3 | C6: =B6/ SUM($B$2:$B$13) -> 0.075735556 | D6: =SUM($C$2:C6) -> 0.76947498 | E6: A | I6: Baby Food | J6: 11314417 | K6: =J6 / SUM($J$2:$J$13) -> 0.082828536 | L6: =SUM($K$2:K6) -> 0.8301102 | M6: =IF(L6<=0.8,"A",IF(L6<=0.95,"B","C")) -> B | Q6: Clothes | R6: =VLOOKUP(A6,$A$2:$E$13,5,FALSE) -> A | S6: =VLOOKUP(A6,$I$2:$M$13,5,FALSE) -> B | T6: =VLOOKUP(Q6,$A$2:$E$13,2,FALSE) -> 2953663.3 | U6: =VLOOKUP(Q6,$I$2:$M$13,2,FALSE) -> 7208005.2
A7: Cereal | B7: 2500898.4 | C7: =B7/ SUM($B$2:$B$13) -> 0.064126107 | D7: =SUM($C$2:C7) -> 0.83360109 | E7: B | I7: Clothes | J7: 7208005.2 | K7: =J7 / SUM($J$2:$J$13) -> 0.052767059 | L7: =SUM($K$2:K7) -> 0.88287726 | M7: =IF(L7<=0.8,"A",IF(L7<=0.95,"B","C")) -> B | Q7: Cereal | R7: =VLOOKUP(A7,$A$2:$E$13,5,FALSE) -> B | S7: =VLOOKUP(A7,$I$2:$M$13,5,FALSE) -> A | T7: =VLOOKUP(Q7,$A$2:$E$13,2,FALSE) -> 2500898.4 | U7: =VLOOKUP(Q7,$I$2:$M$13,2,FALSE) -> 18445875
A8: Vegetables | B8: 2204971.7 | C8: =B8/ SUM($B$2:$B$13) -> 0.056538184 | D8: =SUM($C$2:C8) -> 0.89013927 | E8: B | I8: Vegetables | J8: 5871950.6 | K8: =J8 / SUM($J$2:$J$13) -> 0.042986312 | L8: =SUM($K$2:K8) -> 0.92586357 | M8: =IF(L8<=0.8,"A",IF(L8<=0.95,"B","C")) -> B | Q8: Vegetables | R8: =VLOOKUP(A8,$A$2:$E$13,5,FALSE) -> B | S8: =VLOOKUP(A8,$I$2:$M$13,5,FALSE) -> B | T8: =VLOOKUP(Q8,$A$2:$E$13,2,FALSE) -> 2204971.7 | U8: =VLOOKUP(Q8,$I$2:$M$13,2,FALSE) -> 5871950.6
A9: Meat | B9: 1777615.2 | C9: =B9/ SUM($B$2:$B$13) -> 0.045580238 | D9: =SUM($C$2:C9) -> 0.93571951 | E9: B | I9: Snacks | J9: 3841267.3 | K9: =J9 / SUM($J$2:$J$13) -> 0.028120454 | L9: =SUM($K$2:K9) -> 0.95398403 | M9: =IF(L9<=0.8,"A",IF(L9<=0.95,"B","C")) -> C | Q9: Meat | R9: =VLOOKUP(A9,$A$2:$E$13,5,FALSE) -> B | S9: =VLOOKUP(A9,$I$2:$M$13,5,FALSE) -> C | T9: =VLOOKUP(Q9,$A$2:$E$13,2,FALSE) -> 1777615.2 | U9: =VLOOKUP(Q9,$I$2:$M$13,2,FALSE) -> 2645122.4
A10: Snacks | B10: 1267739.6 | C10: =B10/ SUM($B$2:$B$13) -> 0.032506402 | D10: =SUM($C$2:C10) -> 0.96822591 | E10: C | I10: Meat | J10: 2645122.4 | K10: =J10 / SUM($J$2:$J$13) -> 0.019363933 | L10: =SUM($K$2:K10) -> 0.97334796 | M10: =IF(L10<=0.8,"A",IF(L10<=0.95,"B","C")) -> C | Q10: Snacks | R10: =VLOOKUP(A10,$A$2:$E$13,5,FALSE) -> C | S10: =VLOOKUP(A10,$I$2:$M$13,5,FALSE) -> C | T10: =VLOOKUP(Q10,$A$2:$E$13,2,FALSE) -> 1267739.6 | U10: =VLOOKUP(Q10,$I$2:$M$13,2,FALSE) -> 3841267.3
A11: Personal Care | B11: 648828.46 | C11: =B11/ SUM($B$2:$B$13) -> 0.016636759 | D11: =SUM($C$2:C11) -> 0.98486267 | E11: C | I11: Personal Care | J11: 2116071.4 | K11: =J11 / SUM($J$2:$J$13) -> 0.015490952 | L11: =SUM($K$2:K11) -> 0.98883891 | M11: =IF(L11<=0.8,"A",IF(L11<=0.95,"B","C")) -> C | Q11: Personal Care | R11: =VLOOKUP(A11,$A$2:$E$13,5,FALSE) -> C | S11: =VLOOKUP(A11,$I$2:$M$13,5,FALSE) -> C | T11: =VLOOKUP(Q11,$A$2:$E$13,2,FALSE) -> 648828.46 | U11: =VLOOKUP(Q11,$I$2:$M$13,2,FALSE) -> 2116071.4
A12: Beverages | B12: 491054.37 | C12: =B12/ SUM($B$2:$B$13) -> 0.012591237 | D12: =SUM($C$2:C12) -> 0.99745391 | E12: C | I12: Beverages | J12: 1140195.1 | K12: =J12 / SUM($J$2:$J$13) -> 0.0083469337 | L12: =SUM($K$2:K12) -> 0.99718585 | M12: =IF(L12<=0.8,"A",IF(L12<=0.95,"B","C")) -> C | Q12: Beverages | R12: =VLOOKUP(A12,$A$2:$E$13,5,FALSE) -> C | S12: =VLOOKUP(A12,$I$2:$M$13,5,FALSE) -> C | T12: =VLOOKUP(Q12,$A$2:$E$13,2,FALSE) -> 491054.37 | U12: =VLOOKUP(Q12,$I$2:$M$13,2,FALSE) -> 1140195.1
A13: Fruits | B13: 99296.82 | C13: =B13/ SUM($B$2:$B$13) -> 0.0025460924 | D13: =SUM($C$2:C13) -> 1 | E13: C | I13: Fruits | J13: 384414.66 | K13: =J13 / SUM($J$2:$J$13) -> 0.0028141532 | L13: =SUM($K$2:K13) -> 1 | M13: =IF(L13<=0.8,"A",IF(L13<=0.95,"B","C")) -> C | Q13: Fruits | R13: =VLOOKUP(A13,$A$2:$E$13,5,FALSE) -> C | S13: =VLOOKUP(A13,$I$2:$M$13,5,FALSE) -> C | T13: =VLOOKUP(Q13,$A$2:$E$13,2,FALSE) -> 99296.82 | U13: =VLOOKUP(Q13,$I$2:$M$13,2,FALSE) -> 384414.66
A15: Total | B15: =SUM(B2:B13) -> 38999691 | C15: =SUM(C2:C13) -> 1 | I15: Total | J15: =SUM(J2:J13) -> 1.3660047e+08 | K15: =SUM(K2:K13) -> 1
W19: Key Insights:
W20: • A categories generate the majority of revenue and profit
W21: • Cereal has high revenue but lower profit, indicating lower margins
W22: • Cereal has high revenue but lower profit, indicating lower margins
W23: • C categories contribute minimally and may require optimization
A41: Category | B41: Total cost | C41: % of total | D41: Cumulative % | E41: ABC
A42: Office Supplies | B42: 27578774 | C42: =B42/SUM($B$42:$B$53) -> 0.28256714 | D42: =SUM($C$42:C42) -> 0.28256714 | E42: =IF(D2<=0.8,"A",IF(D2<=0.95,"B","C")) -> A
A43: Household | B43: 16680308 | C43: =B43/SUM($B$42:$B$53) -> 0.17090342 | D43: =SUM($C$42:C43) -> 0.45347056 | E43: =IF(D3<=0.8,"A",IF(D3<=0.95,"B","C")) -> A
A44: Cosmetics | B44: 16407302 | C44: =B44/SUM($B$42:$B$53) -> 0.16810626 | D44: =SUM($C$42:C44) -> 0.62157681 | E44: =IF(D4<=0.8,"A",IF(D4<=0.95,"B","C")) -> A
A45: Meat | B45: 15944976 | C45: =B45/SUM($B$42:$B$53) -> 0.16336935 | D45: =SUM($C$42:C45) -> 0.78494616 | E45: =IF(D5<=0.8,"A",IF(D5<=0.95,"B","C")) -> A
A46: Snacks | B46: 7225565.8 | C46: =B46/SUM($B$42:$B$53) -> 0.074031842 | D46: =SUM($C$42:C46) -> 0.858978 | E46: =IF(D6<=0.8,"A",IF(D6<=0.95,"B","C")) -> A
A47: Vegetables | B47: 4254341.9 | C47: =B47/SUM($B$42:$B$53) -> 0.043589219 | D47: =SUM($C$42:C47) -> 0.90256722 | E47: =IF(D7<=0.8,"A",IF(D7<=0.95,"B","C")) -> B
A48: Baby Food | B48: 3666978.8 | C48: =B48/SUM($B$42:$B$53) -> 0.037571203 | D48: =SUM($C$42:C48) -> 0.94013843 | E48: =IF(D8<=0.8,"A",IF(D8<=0.95,"B","C")) -> B
A49: Beverages | B49: 2573527.7 | C49: =B49/SUM($B$42:$B$53) -> 0.0263679 | D49: =SUM($C$42:C49) -> 0.96650633 | E49: =IF(D9<=0.8,"A",IF(D9<=0.95,"B","C")) -> B
A50: Personal Care | B50: 1467243 | C50: =B50/SUM($B$42:$B$53) -> 0.015033107 | D50: =SUM($C$42:C50) -> 0.98153943 | E50: =IF(D10<=0.8,"A",IF(D10<=0.95,"B","C")) -> C
A51: Clothes | B51: 867507.2 | C51: =B51/SUM($B$42:$B$53) -> 0.0088883222 | D51: =SUM($C$42:C51) -> 0.99042776 | E51: =IF(D11<=0.8,"A",IF(D11<=0.95,"B","C")) -> C
A52: Cereal | B52: 649140.73 | C52: =B52/SUM($B$42:$B$53) -> 0.0066509787 | D52: =SUM($C$42:C52) -> 0.99707873 | E52: =IF(D12<=0.8,"A",IF(D12<=0.95,"B","C")) -> C
A53: Fruits | B53: 285117.84 | C53: =B53/SUM($B$42:$B$53) -> 0.0029212659 | D53: =SUM($C$42:C53) -> 1 | E53: =IF(D13<=0.8,"A",IF(D13<=0.95,"B","C")) -> C
A55: Total | B55: =SUM(B42:B53) -> 97600783 | C55: =SUM(C42:C53) -> 1
